<?xml version='1.0'?>
<sdf version='1.6'>
  <model name='martlet1'>
    <include>
      <uri>model://plane</uri>
    </include>

    <include>
      <uri>model://ptgrey_8mm_camera</uri>
    </include>
    <joint name="camera_wide_joint" type="revolute2">
      <parent>plane::base_link</parent>
      <child>ptgrey_8mm_camera::link</child>
    </joint>

    <include>
      <uri>model://ptgrey_75mm_camera</uri>
    </include>
    <joint name="camera_zoom_joint" type="revolute2">
      <parent>plane::base_link</parent>
      <child>ptgrey_75mm_camera::link</child>
    </joint>
  </model>
</sdf>
